Workbook

Sheet Estimado_HH
A1: Etapas | B1: HORAS POR ACTIVIDAD O ENTREGABLE
A2: Sprint 1 | Planificación, Análisis y Diseño | B2: JP | C2: AP | D2: DBA | E2: QA | F2: DI
A3: Organización del equipo | B3: 4 | C3: 0 | D3: 0 | E3: 0 | F3: 0 | H3: SIGLA | I3: ROL | J3: Costo REMU. HORA HOMBRE(Por Dia) | K3: Suma HH | L3: Suma Costo Total
A4: Definicion Proyecto APT | B4: 6 | C4: 2 | D4: 0 | E4: 0 | F4: 0 | H4: JP | I4: Jefe de Proyecto | J4: 14339 | K4: =B49 -> 40 | L4: =J4*K4 -> 573560
A5: Documentos Individuales | B5: 0 | C5: 4 | D5: 0 | E5: 0 | F5: 2 | H5: AP | I5: Analista Programador | J5: 6828 | K5: =C49 -> 100 | L5: =C48 -> 682800
A6: Acta de Constitución de proyecto | B6: 4 | C6: 2 | D6: 0 | E6: 0 | F6: 0 | H6: DBA | I6: Desarrollador BD | J6: 6875 | K6: =D49 -> 14 | L6: =D48 -> 96250
A7: Aprobación del Acta | B7: 2 | C7: 0 | D7: 0 | E7: 0 | F7: 0 | H7: QA | I7: Calidad Y Testing | J7: 9125 | K7: =E49 -> 22 | L7: =E48 -> 200750
A8: Definición de requerimientos Generales | B8: 2 | C8: 6 | D8: 0 | E8: 0 | F8: 2 | H8: DI | I8: Diseñador | J8: 2835 | K8: =F49 -> 48 | L8: =F48 -> 136080
A9: Captura de requerimientos específicos | B9: 0 | C9: 6 | D9: 0 | E9: 0 | F9: 2 | L9: =SUM(L4:L8) -> 1689440
A10: Documento de casos de uso extendido | B10: 2 | C10: 6 | D10: 0 | E10: 0 | F10: 2
A11: Prototipos | B11: 0 | C11: 0 | D11: 0 | E11: 0 | F11: 6 | H11: Costo por Fase/Sprint | I11: Costo Total
A12: Propuesta ERS | B12: 2 | C12: 4 | D12: 0 | E12: 0 | F12: 2 | H12: Sprint 1 | I12: =SUM(B16:F16) -> 627318
A13: Matriz EDT | B13: 2 | C13: 0 | D13: 0 | E13: 0 | F13: 0 | H13: Sprint 2 | I13: =SUM(B27:F27) -> 403524
A14: Documentos de Presentación de Proyecto | B14: 0 | C14: 4 | D14: 0 | E14: 0 | F14: 2 | H14: Sprint 3 | I14: =SUM(B34:F34) -> 263618
A15: Horas Hombre | B15: =SUM(B3:B14) -> 24 | C15: =SUM(C3:C14) -> 34 | D15: =SUM(D3:D14) -> 0 | E15: =SUM(E3:E14) -> 0 | F15: =SUM(F3:F14) -> 18 | H15: Sprint 4 | I15: =SUM(B41:F41) -> 308324
A16: Costo Por Fase | B16: =B15*J4 -> 344136 | C16: =C15*J5 -> 232152 | D16: =D15*J6 -> 0 | E16: =E15*J7 -> 0 | F16: =F15*J8 -> 51030 | H16: Sprint 5 | I16: =SUM(B46:F46) -> 86656
A17: Sprint 2 | Desarrollo de la aplicación móvil | B17: JP | C17: AP | D17: DBA | E17: QA | F17: DI | H17: Costo Total Proyecto | I17: =SUM(I12:I16) -> 1689440
A18: Documento de arquitectura SW | B18: 2 | C18: 6 | D18: 0 | E18: 0 | F18: 2
A19: Implementación del ambiente de desarrollo | B19: 2 | C19: 6 | D19: 2 | E19: 0 | F19: 2
A20: Creación de scripts de tablas base de datos (Firebase / Firestore o SQL) | B20: 0 | C20: 2 | D20: 4 | E20: 0 | F20: 0
A21: Creación de scripts de consultas / lógica de backend | B21: 0 | C21: 4 | D21: 2 | E21: 0 | F21: 0
A22: Desarrollo de módulos principales: | B22: 0 | C22: 6 | D22: 0 | E22: 0 | F22: 4
A23: Autenticación y gestión de usuarios | B23: 0 | C23: 6 | D23: 0 | E23: 0 | F23: 4
A24: Notificaciones | B24: 0 | C24: 6 | D24: 0 | E24: 0 | F24: 4
A25: Reportes
A26: Horas Hombre | B26: =SUM(B18:B25) -> 4 | C26: =SUM(C18:C25) -> 36 | D26: =SUM(D18:D25) -> 8 | E26: =SUM(E18:E25) -> 0 | F26: =SUM(F18:F25) -> 16
A27: Costo Por Fase | B27: =B26*J4 -> 57356 | C27: =C26*J5 -> 245808 | D27: =D26*J6 -> 55000 | E27: =E26*J7 -> 0 | F27: =F26*J8 -> 45360
A28: Sprint 3 | Integración y pruebas del sistema | B28: JP | C28: AP | D28: DBA | E28: QA | F28: DI
A29: ntegración de módulos desarrollados | B29: 2 | C29: 6 | D29: 2 | E29: 0 | F29: 2
A30: Pruebas unitarias y de integración | B30: 0 | C30: 2 | D30: 0 | E30: 6 | F30: 0
A31: Ajustes y optimización de código | B31: 0 | C31: 4 | D31: 0 | E31: 2 | F31: 0
A32: Validación de funcionalidades según requerimientos | B32: 2 | C32: 2 | D32: 0 | E32: 2 | F32: 0
A33: Horas Hombre | B33: =SUM(B29:B32) -> 4 | C33: =SUM(C29:C32) -> 14 | D33: =SUM(D29:D32) -> 2 | E33: =SUM(E29:E32) -> 10 | F33: =SUM(F29:F32) -> 2
A34: Costo Por Fase | B34: =B33*J4 -> 57356 | C34: =C33*J5 -> 95592 | D34: =D33*J6 -> 13750 | E34: =E33*J7 -> 91250 | F34: =F33*J8 -> 5670
A35: Sprint 4 | Certificación QA y puesta en marcha de la app | B35: JP | C35: AP | D35: DBA | E35: QA | F35: DI
A36: Implementación del ambiente de pruebas | B36: 2 | C36: 2 | D36: 2 | E36: 2 | F36: 0
A37: Pruebas funcionales y de usabilidad con usuarios finales | B37: 0 | C37: 2 | D37: 0 | E37: 6 | F37: 2
A38: Corrección de errores y ajustes finales | B38: 2 | C38: 4 | D38: 0 | E38: 4 | F38: 2
A39: Migración de la app a producción (Google Play / App Store) | B39: 2 | C39: 2 | D39: 2 | E39: 0 | F39: 2
A40: Horas Hombre | B40: =SUM(B36:B39) -> 6 | C40: =SUM(C36:C39) -> 10 | D40: =SUM(D36:D39) -> 4 | E40: =SUM(E36:E39) -> 12 | F40: =SUM(F36:F39) -> 6
...

Sheet Gastos_Operacionales
A2: Gastos Operacionales
A3: Firebase+Storage(estimación anual) | B3: 171000
A4: Publicsción Android (pago unico) | B4: 23750
A5: Roboflow (version free) | B5: 0
A6: Internet (12 meses) | B6: =10000*12 -> 120000
A7: Electricidad (12 meses) | B7: =5000*12 -> 60000
A8: Total / Anual | B8: =SUM(B3:B7) -> 374750

Sheet Flujo_Caja
A2: Item | B2: Monto | D2: ITEM | E2: MES 0 | F2: AGOSTO | G2: SEPTIEMBRE | H2: OCTUBRE | I2: NOVIEMBRE | J2: DICIEMBRE | L2: VAN | M2: 21246865
A3: Recursos Humanos | B3: =Estimado_HH!I17 -> 1689440 | D3: ARRASTRE | E3: 0 | F3: =E22 -> 4238136.8 | G3: =F22 -> 4893228.8 | H3: =G22 -> 5793023.6 | I3: =H22 -> 6855305.9 | J3: =I22 -> 7897270.2 | L3: TIR | M3: 1.29
A4: Contingencia (10%) | B4: =B3*0.1 -> 168944 | D4: PRESTAMO | E4: 3000000
A5: Total Inversión | B5: =SUM(B3:B4) -> 1858384 | D5: APORTE ACTIVOS | E5: 1500000
D6: HITO DE PAGOS | E6: 0 | F6: 0 | G6: 0 | H6: 0 | I6: 0 | J6: 0
D7: Usuario Estimado | E7: =$B$14 -> 2000 | F7: =$B$14* POWER(1+$B$15, 1) -> 2160 | G7: =$B$14* POWER(1+$B$15, 2) -> 2332.8 | H7: =$B$14* POWER(1+$B$15, 3) -> 2519.424 | I7: =$B$14* POWER(1+$B$15, 4) -> 2720.9779 | J7: =$B$14* POWER(1+$B$15, 5) -> 2938.6562
D8: Ingreso Suscripciones | F8: =F7*$B$16*$B$17 -> 259200 | G8: =G7*$B$16*$B$17 -> 279936 | H8: =H7*$B$16*$B$17 -> 302330.88 | I8: =I7*$B$16*$B$17 -> 326517.35 | J8: =J7*$B$16*$B$17 -> 352638.74
A9: Concepto | B9: Monto | D9: Ingreso Descargas | F9: =$B$18*$B$21 -> 1200000 | G9: =$B$18*$B$21 -> 1200000 | H9: =$B$18*$B$21 -> 1200000 | I9: =$B$18*$B$21 -> 1200000 | J9: =$B$18*$B$21 -> 1200000
A10: Firebase+Storgae (Mensual) | B10: 34200 | D10: INGRESO TOTAL | E10: =SUM(E3:E6) -> 4500000 | F10: =SUM(F3:F9) -> 5699496.8 | G10: =SUM(G3:G9) -> 6375497.6 | H10: =SUM(H3:H9) -> 7297873.9 | I10: =SUM(I3:I9) -> 8384544.2 | J10: =SUM(J3:J9) -> 9452847.6
A11: Internet (Estimada 1 Año) | B11: 120000 | D11: LUZ | E11: 0 | F11: 5000 | G11: 5000 | H11: 5000 | I11: 5000 | J11: 5000
A12: Electricidad (Estimada 1 Año) | B12: 60000 | D12: INTERNET | E12: 0 | F12: 10000 | G12: 10000 | H12: 10000 | I12: 10000 | J12: 10000
A13: Publicacion Android (Pago Unico) | B13: 23750 | D13: PUBLICACIÓN ANDROID | E13: 0 | F13: 4750 | G13: 4750 | H13: 4750 | I13: 4750 | J13: 4750
A14: Usuarios iniciales | B14: 2000 | D14: FIREBASE+STORAGE(mensual) | E14: 0 | F14: 34200 | G14: 34200 | H14: 34200 | I14: 34200 | J14: 34200
A15: Crecimiento mensual usuarios | B15: 0.08 | D15: SUELDOS(Sprints) | E15: 0 | F15: =Estimado_HH!I12 -> 627318 | G15: =Estimado_HH!I13 -> 403524 | H15: =Estimado_HH!I14 -> 263618 | I15: =Estimado_HH!I15 -> 308324 | J15: =Estimado_HH!I16 -> 86656
A16: Tasa conversión a suscripción | B16: 0.04 | D16: CONTINGENCIA (10%) | E16: =B4 -> 168944 | F16: 0 | G16: 0 | H16: 0 | I16: 0 | J16: 0
A17: Precio suscripción mensual | B17: 3000 | D17: RESERVA(5%) | E17: =B5*0.05 -> 92919.2 | F17: 0 | G17: 0 | H17: 0 | I17: 0 | J17: 0
A18: Descargas mensuales | B18: 800 | D18: AMORTIZACIÓN (Mensual) | E18: 0 | F18: =IF($B$22>0,$E$5/$B$22,0) -> 125000 | G18: =IF($B$22>0,$E$5/$B$22,0) -> 125000 | H18: =IF($B$22>0,$E$5/$B$22,0) -> 125000 | I18: =IF($B$22>0,$E$5/$B$22,0) -> 125000 | J18: =IF($B$22>0,$E$5/$B$22,0) -> 125000
A19: Impuesto (%) | B19: 0.25 | D19: EGRESOS Totales | E19: =SUM(E11:E18) -> 261863.2 | F19: =SUM(F11:F18) -> 806268 | G19: =SUM(G11:G18) -> 582474 | H19: =SUM(H11:H18) -> 442568 | I19: =SUM(I11:I18) -> 487274 | J19: =SUM(J11:J18) -> 265606
A20: Tasa descuento anual (Para VAN) | B20: 0.1 | D20: Utilidad antes impuestos | E20: 0 | F20: =F10-F19-F18 -> 4768228.8 | G20: =G10-G19-G18 -> 5668023.6 | H20: =H10-H19-H18 -> 6730305.9 | I20: =I10-I19-I18 -> 7772270.2 | J20: =J10-J19-J18 -> 9062241.6
A21: Ingreso por descarga (CLP) | B21: 1500 | D21: Impuesto (25%) | F21: =MAX(0, F19*$B$19) -> 201567 | G21: =MAX(0, G19*$B$19) -> 145618.5 | H21: =MAX(0, H19*$B$19) -> 110642 | I21: =MAX(0, I19*$B$19) -> 121818.5 | J21: =MAX(0, J19*$B$19) -> 66401.5
A22: vida util amortización (meses) | B22: 12 | D22: FLUJOS | E22: =E10-E19 -> 4238136.8 | F22: =F10-F19 -> 4893228.8 | G22: =G10-G19 -> 5793023.6 | H22: =H10-H19 -> 6855305.9 | I22: =I10-I19 -> 7897270.2 | J22: =J10-J19 -> 9187241.6
A23: Tasa descuento mensual | B23: =POWER(1+B20,1/12)-1 -> 0.0079741404

Sheet VAR_TIR
C18: =Flujo_Caja!E2 -> MES 0 | D18: =Flujo_Caja!F2 -> AGOSTO | E18: =Flujo_Caja!G2 -> SEPTIEMBRE | F18: =Flujo_Caja!H2 -> OCTUBRE | G18: =Flujo_Caja!I2 -> NOVIEMBRE | H18: =Flujo_Caja!J2 -> DICIEMBRE
B19: Inversion inicial | C19: =Flujo_Caja!E22 -> 4238136.8
B20: =Flujo_Caja!D22 -> FLUJOS | C20: =-Flujo_Caja!E22 -> -4238136.8 | D20: =Flujo_Caja!F22 -> 4893228.8 | E20: =Flujo_Caja!G22 -> 5793023.6 | F20: =Flujo_Caja!H22 -> 6855305.9 | G20: =Flujo_Caja!I22 -> 7897270.2 | H20: =Flujo_Caja!J22 -> 9187241.6
B23: Tasa descuento anual | C23: 0.1
B27: VAN | C27: =NPV(C23,D20:H20)+C20 -> 21246865
B28: TIR | C28: =IRR(C20:H20) -> 1.292086
